Workbook

Sheet PONDERATION
T1: DOMAINE | U1: POID | V1: DOMAINE | W1: POID | X1: DOMAINE | Y1: POID | Z1: DOMAINE | AA1: POID | AB1: DOMAINE | AC1: POID | AD1: DOMAINE | AE1: POID
T2: GOV | U2: 23 | V2: INC | W2: 12 | X2: CRI | Y2: 35 | Z2: CONT | AA2: 23 | AB2: FOR | AC2: 3 | AD2: CONF | AE2: 4
C3: AHP | K3: Echelle | N3: Domaine | O3: Nb Questions / Domaine | P3: Arrondissement | Q3: Real
D4: GOV | E4: INC | F4: CRI | G4: CONT | H4: FOR | I4: CONF | K4: 1 : importance égale | N4: GOV | O4: =(72/100)*L16 -> 19.08 | P4: 18 | Q4: 18
C5: GOV | D5: 1 | E5: 4 | F5: 0.75 | G5: 1 | H5: 5 | I5: 4 | K5: 3 : importance modérée | N5: INC | O5: =(72/100)*L17 -> 13.32 | P5: 17 | Q5: 17
C6: INC | D6: 0.25 | E6: 1 | F6: 0.66666667 | G6: 0.25 | H6: 4 | I6: 3 | K6: 5 : importance forte | N6: CRI | O6: =(72/100)*L18 -> 14.4 | P6: 20 | Q6: 22
C7: CRI | D7: 4 | E7: 1.5 | F7: 1 | G7: 2 | H7: 7 | I7: 6 | K7: 7 : importance très forte | N7: CONT | O7: =(72/100)*L19 -> 16.56 | P7: 11 | Q7: 11
C8: CONT | D8: 1 | E8: 4 | F8: 0.5 | G8: 1 | H8: 6 | I8: 5 | K8: 9 : importance extrême | N8: FOR | O8: =(72/100)*L20 -> 4.32 | P8: 3 | Q8: 3
C9: FOR | D9: 0.2 | E9: 0.25 | F9: 0.14285714 | G9: 0.16666667 | H9: 1 | I9: 0.66666667 | K9: 2, 4, 6, 8 : valeurs intermédiaires | N9: CONF | O9: =(72/100)*L21 -> 4.32 | P9: 3 | Q9: 4
C10: CONF | D10: 0.25 | E10: 0.33333333 | F10: 0.16666667 | G10: 0.2 | H10: 1.5 | I10: 1 | N10: Nombre De Question | O10: =SUM(O4:O9) -> 72 | P10: =SUM(P4:P9) -> 72 | Q10: =SUM(Q4:Q9) -> 75
C11: SOMME | D11: =SUM(D5:D10) -> 6.7 | E11: =SUM(E5:E10) -> 11.083333 | F11: =SUM(F5:F10) -> 3.2261905 | G11: =SUM(G5:G10) -> 4.6166667 | H11: =SUM(H5:H10) -> 24.5 | I11: =SUM(I5:I10) -> 19.666667
C13: NORMALISER : Méthode approchée par normalisation des colonnes
C14: Domaine | J14: PONDERATION | L14: Arrondissement
D15: GOV | E15: INC | F15: CRI | G15: CONT | H15: FOR | I15: CONF | J15: Resultat | K15: % | L15: Final
C16: GOV | D16: =D5/D11 -> 0.14925373 | E16: =E5/E11 -> 0.36090226 | F16: =F5/F11 -> 0.23247232 | G16: =G5/G11 -> 0.2166065 | H16: =H5/H11 -> 0.20408163 | I16: =I5/I11 -> 0.20338983 | J16: =SUM(D16:I16)/6 -> 0.22778438 | K16: =J16*100 -> 22.778438 | L16: 26.5
C17: INC | D17: =D6/D11 -> 0.037313433 | E17: =E6/E11 -> 0.090225564 | F17: =F6/F11 -> 0.20664207 | G17: =G6/G11 -> 0.054151625 | H17: =H6/H11 -> 0.16326531 | I17: =I6/I11 -> 0.15254237 | J17: =SUM(D17:I17)/6 -> 0.11735673 | K17: =J17*100 -> 11.735673 | L17: 18.5
C18: CRI | D18: =D7/D11 -> 0.59701493 | E18: =E7/E11 -> 0.13533835 | F18: =F7/F11 -> 0.3099631 | G18: =G7/G11 -> 0.433213 | H18: =H7/H11 -> 0.28571429 | I18: =I7/I11 -> 0.30508475 | J18: =SUM(D18:I18)/6 -> 0.34438807 | K18: =J18*100 -> 34.438807 | L18: 20
C19: CONT | D19: =D8/D11 -> 0.14925373 | E19: =E8/E11 -> 0.36090226 | F19: =F8/F11 -> 0.15498155 | G19: =G8/G11 -> 0.2166065 | H19: =H8/H11 -> 0.24489796 | I19: =I8/I11 -> 0.25423729 | J19: =SUM(D19:I19)/6 -> 0.23014655 | K19: =J19*100 -> 23.014655 | L19: 23
C20: FOR | D20: =D9/D11 -> 0.029850746 | E20: =E9/E11 -> 0.022556391 | F20: =F9/F11 -> 0.044280443 | G20: =G9/G11 -> 0.036101083 | H20: =H9/H11 -> 0.040816327 | I20: =I9/I11 -> 0.033898305 | J20: =SUM(D20:I20)/6 -> 0.034583882 | K20: =J20*100 -> 3.4583882 | L20: 6
C21: CONF | D21: =D10/D11 -> 0.037313433 | E21: =E10/E11 -> 0.030075188 | F21: =F10/F11 -> 0.051660517 | G21: =G10/G11 -> 0.0433213 | H21: =H10/H11 -> 0.06122449 | I21: =I10/I11 -> 0.050847458 | J21: =SUM(D21:I21)/6 -> 0.045740397 | K21: =J21*100 -> 4.5740397 | L21: 6
K22: =SUM(K16:K21) -> 100 | L22: =SUM(L16:L21) -> 100

Sheet Questionnaire Gestion Incidents
B1: Domaine | C1: Sous Domaine | D1: Catégorie de contrôle | E1: Contrôle | F1: Objectif | G1: Preuves possibles | H1: Question finale | I1: Refernces | J1: Result | L1: Score Du Domaine | M1: ATTRIBUTE | N1: VALUE
B2: Gestion des incidents | C2: Détection et signalement | D2: Sources de détection | E2: Les sources de détection internes et externes sont-elles identifiées ? | F2: S’assurer que les sources de détection internes et externes sont identifiées afin de permettre une surveillance efficace et proactive des incidents. | G2: Liste des sources de détection ; documentation SOC/SIEM ; cartographie des alertes | H2: What technical resources and tools are implemented to support threat detection and monitoring? | I2: NIST 800-61r3 – DE.CM-01 / DE.CM-09 CSF 2.0 – DE.CM (Continuous Monitoring) 27002 – 8.15 / 8.16 | J2: N/A | L2: =N2/R2 -> 0.875 | M2: Yes | N2: =COUNTIF(J2:J24,"Yes") -> 14 | O2: Nb Question | P2: =COUNTA(H2:H24) -> 17 | Q2: Nb Question App | R2: =P2-N4 -> 16
D3: Registre des incidents | E3: Existe-t-il un registre ou un outil de ticketing pour tracer les incidents ? | F3: S’assurer qu’un registre ou un outil de ticketing est utilisé pour tracer les incidents afin d’assurer la traçabilité et le suivi. | G3: Registre des incidents ; outil de ticketing ; rapports de suivi des incidents | H3: Is a formal incident logging register or ticketing system implemented to ensure proper tracking, documentation, and traceability of incidents? | I3: NIST 800-61r3 – RS.MA-03 / RS.AN-06 CSF 2.0 – RS.MA (Incident Management) 27002 – 5.25 / 5.26 | J3: No | M3: No | N3: =COUNTIF(J2:J24,"No") -> 2
C4: Confinement, éradication et remédiation | D4: Procédure d’éradication | E4: Les actions d’éradication de la menace sont-elles documentées ? | F4: S’assurer que les actions d’éradication de la menace sont documentées afin de neutraliser efficacement les causes des incidents. | G4: Procédure d’éradication ; runbooks techniques ; rapports d’intervention | H4: What eradication actions are defined to address identified threats? | I4: NIST 800-61r3 – RS.MI-02 / RS.AN-03 CSF 2.0 – RS.MI (Incident Mitigation) 27002 – 5.26 | J4: Yes | M4: N/A | N4: =COUNTIF(J2:J24,"N/A") -> 1
C5: Securite Physique | D5: Périmètres de sécurité physique | E5: Mise en place de contrôles d’accès physique, surveillance et protection des sites | F5: Assurer la protection des infrastructures critiques contre les accès non autorisés | G5: Contrôles d’accès physiques ; vidéosurveillance ; systèmes d’alarme ; registres d’accès | H5: Comment l’entreprise s’assure-t-elle que les bâtiments hébergeant des systèmes d’information sont physiquement sécurisés, que l’accès physique est contrôlé et limité aux personnes autorisées, et que des systèmes d’alarme et de surveillance sont installés et opérationnels ? | I5: NIST 800-61r3 – DE.CM-02 / PR.AA-06 CSF 2.0 – PR.AA (Physical Access) 27002 – 7.1 / 7.2 / 7.4 | J5: Yes | M5: Auditeur | N5: Oumayma
C6: Fonctionnement | D6: Terminaux finaux des utilisateurs | E6: Définition des exigences de sécurité des logiciels et gestion des mises à jour | F6: Assurer la sécurité et la conformité des terminaux utilisateurs | G6: Politique de gestion des correctifs ; inventaire logiciel ; outils de gestion des endpoints | H6: Quelles exigences sont définies concernant les logiciels installés sur les terminaux des utilisateurs finaux, et comment et comment les mises à jour sont-elles assurées ? | I6: NIST 800-61r3 – DE.CM-09 / PR.PS-02 CSF 2.0 – PR.PS (Platform Security) 27002 – 8.1 / 8.8 | J6: Yes
D7: Protection contre les programmes malveillants | E7: Analyse systématique des données entrantes | F7: Prévenir l’introduction de logiciels malveillants via des supports externes ou réseaux | G7: Solutions antivirus ; passerelles de sécurité ; rapports d’analyse | H7: Les données reçues via les réseaux, supports de stockage ou pièces jointes des emails, sont-elles systématiquement analysées avant utilisation ? | I7: NIST 800-61r3 – DE.CM-09 / RS.MI-01 CSF 2.0 – DE.CM-09 27002 – 8.7 | J7: No
E9: Déploiement d’outils anti-malware à jour | F9: Détecter et supprimer les programmes malveillants efficacement | G9: Antivirus/EDR ; journaux de mise à jour ; rapports de détection | H9: Des outils de détection et de suppression des programmes malveillants sont-ils installés et régulièrement mis à jour sur les systèmes ? | I9: NIST 800-61r3 – DE.CM-09 / RS.MI-01 CSF 2.0 – PR.PS / DE.CM 27002 – 8.7 | J9: Yes
D10: Gestion des vulnérabilités techniques | E10: Vérification de l’intégrité des mises à jour | F10: Garantir que seules des mises à jour fiables sont installées | G10: Signatures numériques ; journaux de validation ; politiques de patching | H10: Les mises à jour sont-elles signées numériquement et leur intégrité est-elle vérifiée avant installation | I10: NIST 800-61r3 – ID.RA-09 / PR.PS-02 CSF 2.0 – PR.PS-02 / ID.RA-09 27002 – 8.8 / 8.9 | J10: Yes
E11: Réalisation de tests de sécurité réguliers | F11: Identifier et corriger les vulnérabilités | G11: Rapports de pentest ; scans de vulnérabilités | H11: Des tests de pénétration ou évaluations de vulnérabilités sont-ils réalisés régulièrement par du personnel compétent et autorisé ? | I11: NIST 800-61r3 – ID.IM-02 / ID.RA-05 CSF 2.0 – ID.IM-02 (Tests & Exercises) 27002 – 8.8 | J11: Yes
D13: Prévention de la fuite de données | E13: Mise en place de contrôles d’accès aux données sensibles | F13: Limiter l’accès aux données selon le principe du moindre privilège | G13: Programme de blockage; journaux d’accès ; revues des droits | H13: Les accès aux données sensibles sont-ils protégés par des contrôles d’accès granulaires (RBAC/ABAC) ? | I13: NIST 800-61r3 – PR.AA-05 CSF 2.0 – PR.AA-05 (Least Privilege) 27002 – 5.15 / 8.3 | J13: Yes
E14: Contrôle des périphériques amovibles | F14: Réduire les risques d’exfiltration de données | G14: Politiques USB ; journaux d’accès ; solutions de contrôle des périphériques | H14: Les périphériques amovibles (USB, disques externes) sont-ils contrôlés ? | I14: NIST 800-61r3 – PR.PS-05 CSF 2.0 – PR.PS-05 27002 – 7.10 / 8.1 | J14: Yes
E15: Déploiement de solutions DLP | F15: Prévenir et détecter les fuites de données | G15: Solutions DLP ; rapports d’alerte ; politiques de sécurité | H15: Des solutions DLP sont-elles déployées sur les endpoints, le réseau et le cloud ? | I15: NIST 800-61r3 – DE.CM-09 / PR.DS-01 CSF 2.0 – PR.DS (Data Security) 27002 – 8.12 | J15: Yes
D16: Redondance des moyens de traite- ment de l'infor- mation | E16: Mise en place de mécanismes de redondance des systèmes critiques | F16: Assurer la continuité de service | G16: Architectures redondantes ; documentation technique ; tests de bascule | H16: L’architecture des systèmes intègre-t-elle des mécanismes de redondance (active-active, active-passive) adaptés aux besoins métier ? (fourniseur internet , power suply , service acess ) | I16: NIST 800-61r3 – PR.IR-03 / PR.IR-04 CSF 2.0 – PR.IR (Infrastructure Resilience) 27002 – 8.14 | J16: Yes
D19: Sécurité des réseaux | E19: Sauvegarde et gestion des configurations réseau | F19: Assurer l’intégrité et la restauration des configurations | G19: Sauvegardes de configuration ; outils de gestion réseau ; historiques de version | H19: Les configurations réseau sont-elles sauvegardées et versionnées pour assurer leur intégrité et leur restauration ? | I19: NIST 800-61r3 – PR.PS-01 / RC.RP-03 CSF 2.0 – PR.PS-01 / RC.RP 27002 – 8.9 / 8.13 | J19: Yes
E20: Segmentation réseau et contrôle des protocoles | F20: Limiter la propagation des menaces | G20: Architecture réseau ; VLAN ; règles de filtrage ; documentation des protocoles | H20: Le réseau est-il correctement segmenté, et quels protocoles sont autorisés au sein du réseau ? | J20: Yes
I21: NIST 800-61r3 – PR.IR-01 / DE.CM-01 CSF 2.0 – PR.IR-01 / DE.CM-01 27002 – 8.20 / 8.22
E22: Mise en place de contrôles d’accès réseau | F22: Protéger les ressources réseau contre les accès non autorisés | G22: Firewalls ; ACL ; journaux de filtrage ; configurations réseau | H22: Des contrôles d’accès réseau (firewalls, ACL) sont-ils configurés ? | I22: NIST 800-61r3 – PR.IR-01 / DE.CM-01 CSF 2.0 – PR.AA / PR.IR-01 27002 – 8.20 / 8.21 | J22: Yes
D23: Utilisation de la cryptographie | E23: Chiffrement des données et gestion des impacts sur la sécurité | F23: Protéger la confidentialité et l’intégrité des données | G23: certificats ; journaux ; outils d’inspection TLS | H23: Les données au repos et en transit sont-elles chiffrées, et des mécanismes sont-ils en place pour gérer l’impact du chiffrement sur les contrôles de sécurité (Inspection, détection et analyse) ? | I23: NIST 800-61r3 – PR.DS-01 / PR.DS-02 CSF 2.0 – PR.DS (Data Security) 27002 – 8.24 | J23: Yes

Sheet Questionnaire Confirmitee
L2: Nb Question | N2: Yes | O2: No | P2: N/A | Q2: Nb App | R2: SCORE DU DOMAIN
B3: Domaine | C3: Sous Domaine | D3: Catégorie de contrôle | E3: Contrôle | F3: Objectif | G3: Preuves possibles | H3: Question finale | I3: Result | L3: =COUNTA(I4:I13) -> 4 | N3: =COUNTIF(I4:I12,"Yes") -> 2 | O3: =COUNTIF(I4:I12,"No") -> 1 | P3: =COUNTIF(I4:I12,"N/A") -> 1 | Q3: =L3-P3 -> 3 | R3: =N3/Q3 -> 0.66666667
B4: CADRE REGLEMENTAIRE ET JURIDIQUE | C4: Cybersecurity Governance & Protection | D4: l’audit | E4: l’audit obligatoire de la sécurité des systèmes d’information | F4: S’assurer que des audits obligatoires de la sécurité des systèmes d’information sont réalisés afin d’évaluer la conformité et l’efficacité des mesures de sécurité mises en place | G4: Rapport d'audit une fois chaque 12 mois | H4: Pouvez-vous fournir les rapports d’audit réalisés au cours des 12 derniers mois, ainsi que les preuves de leur dépôt auprès de l’ANSI ? | I4: Yes
G5: laudit est effectuée par des experts ou des organisme lisyer par ANSI
G6: organismes soumis à l’audit de sécurité des systèmes d’information remettent à l’Agence une copie électronique protégée du rapport d’audit dans un délai ne dépassant pas dix (10) jours après la fin des opérations d’audit
D7: Sécurité des logiciels et équipements électroniques | E7: Attribution le label « sécurisé » à chaque logiciel ou équipement électronique | F7: S’assurer que chaque logiciel ou équipement électronique obtient un label « sécurisé » afin de garantir qu’il répond aux exigences de sécurité définies. | G7: Document officiele de l'attribution de la label "securise" sur logiciel et equipement de l'entreprise | H7: Est-ce que vos équipements électroniques et logiciels, ainsi que vos fournisseurs de services cloud, possèdent respectivement les labels « Sécurisé » et « G-Cloud / N-Cloud » valides délivrés par l’ANSI ? | I7: N/A | L7: Auditeur | M7: Oumayma
D8: Du classement des fournisseurs des services de l’informatique en nuage et de l’hébergement | E8: Attribution le label « G-Cloud » et « N-Cloud » à chaque Fournisseur de services informatique en nuage | F8: S’assurer que chaque fournisseur de services cloud obtient les labels « G-Cloud » et « N-Cloud » afin de garantir leur conformité aux standards de sécurité applicables. | G8: document officielle de l'attribution et validiter de la label pour les fourniseur et pour l'organisme si applicable
D9: dispositions spécifiques aux infrastructures numériques d’importance vitale | E9: Les structures qui gèrent des infrastructures numériques d’importance vitale sont tenues de prendre les mesures de sécurité | F9: S’assurer que les structures gérant des infrastructures numériques critiques appliquent des mesures de sécurité renforcées afin de protéger les services essentiels | G9: Utiliser des logiciels et équipements ayant le label « sécurisé ». Avoir son propre centre d'hébergement principal et un centre de backup auprès d’un fournisseur de services informatique en nuage ayant obtenu le label. Respecter les mesures et les procédures nécessaires pour assurer la continuité d'activité et protéger les bases de données sensibles dont l'atteinte à l'intégrité pourrait affecter à la sécurité nationale en cas de crise cybernétique | H9: L’organisme dispose-t-il d’un centre de réponse aux urgences (propre ou adhérent) et prend-il les mesures de sécurité requises pour la gestion des infrastructures numériques d’importance vitale ? | I9: No
D10: Réponse aux urgences cybernétiques | E10: Les organismes sont tenues de créer leurs propres centres de réponse aux urgences ou d’adhérer à des centres de réponse aux urgences cybernétiques | F10: S’assurer que les organismes mettent en place ou adhèrent à des centres de réponse aux urgences cybernétiques afin de garantir une capacité efficace de détection et de réponse aux incidents | G10: prezsence d'un centre local ou contrat en cas d'un tier
D11: classification selon le degré de sécurité | E11: Quelle est le niveau de securite ( premier niveau / Deuxieme niveau / Troisieme niveau ) | F11: Evaluation de niveau de securite | G11: Document de classification de ANSI | H11: L’organisation possède-t-elle un niveau de sécurité délivré par l’ANSI ? Si oui, quel est ce niveau ? | I11: Yes

Sheet Questionnaire Gouvernance 
A1: Domaine | B1: Sous Domaine | C1: Catégorie de contrôle | D1: Contrôle | E1: Objectif | F1: Preuves possibles | G1: Question finale | I1: Result | L1: Score Du Domaine | M1: ATTRIBUTE | O1: VALUE
A2: GOUVERNANCE | B2: Cadre de gouvernance et politiques | C2: Articulation avec les dispositifs connexes | D2: Les liens entre gestion de crise, gestion des incidents, continuité d’activité et sécurité sont-ils formalisés ? | E2: S’assurer que les liens entre gestion de crise, gestion des incidents, continuité d’activité et sécurité sont formalisés afin de garantir une coordination efficace et une réponse cohérente face aux disruptions. | F2: Schéma de gouvernance ; matrice d’articulation entre dispositifs ; procédure transversale validée | G2: Les liens entre la gestion de crise, la gestion des incidents, la continuité d’activité et la sécurité sont-ils formalisés ? | I2: No | L2: =O2/S2 -> 0.625 | M2: Yes | O2: =COUNTIF(I2:I37,"Yes") -> 20 | P2: Nb Question | Q2: =COUNTA(I2:I200) -> 35 | R2: Nb Question App | S2: =Q2-O4 -> 32 | T2: Auditeur | U2: Dhia
C3: Existence et approbation du cadre de gouvernance | D3: Le cadre formel de gouvernance de gestion de crise cyber est-il documenté, daté et approuvé par l’autorité compétente ? | E3: S’assurer que le cadre de gouvernance de gestion de crise cyber est formellement documenté, daté et approuvé afin de garantir sa validité, sa légitimité et son application. | F3: Cadre de gouvernance approuvé ; note de validation signée ; version datée du document | G3: Le cadre formel de gouvernance de la gestion de crise cyber est-il documenté, daté et approuvé par l’autorité compétente afin de garantir sa validité et son application ? | I3: Yes | M3: No | O3: =COUNTIF(I2:I37,"No") -> 12
C4: Révision périodique du cadre et des politiques | D4: Existe-t-il une périodicité formelle de révision du cadre de gouvernance et les dernières versions sont-elles datées et tracées ? | E4: S’assurer qu’une périodicité de révision est définie et respectée afin de maintenir le cadre de gouvernance à jour et adapté aux évolutions. | F4: Calendrier de révision ; historique des versions ; journal des modifications | G4: Exsite t-il des cas specifique ou de periode qui declanche la revision du cadre de gouvernance ? | I4: No | M4: N/A | O4: =COUNTIF(I2:I37,"N/A") -> 3
C5: Diffusion du cadre aux parties prenantes concernées | D5: Le cadre de gouvernance est-il communiqué aux parties prenantes concernées et cette diffusion est-elle traçable ? | E5: S’assurer que le cadre de gouvernance est communiqué aux parties prenantes et que cette diffusion est traçable afin de garantir sa bonne appropriation. | F5: Liste de diffusion ; emails de communication ; accusés de réception ou feuilles de diffusion | G5: Existe-t-il une politique qui definie la modaliter et les ligne a suivre en terme de communication interne et externe dans le cas d'un crise cyber ? | I5: N/A
C6: Répartition des responsabilités | D6: Les responsabilités de chaque acteur sont-elles attribuées pour les principales activités de crise ? | E6: S’assurer que les responsabilités de chaque acteur sont formalisées pour les activités de crise afin d’assurer coordination et responsabilité. | F6: Matrice RACI ; répartition des responsabilités ; procédures opérationnelles | G6: Existe-t-il une repartition des responsabilite pour chaque acteur et procedure operationelles ? | I6: Yes
C7: Autorités décisionnelles | D7: Les niveaux d’autorité pour décider, arbitrer et valider en situation de crise sont-ils clairement définis ? | E7: S’assurer que les niveaux d’autorité sont clairement définis afin de permettre une prise de décision rapide et structurée en situation de crise. | F7: Délégations de pouvoir ; matrice d’autorité ; procédure de décision de crise | G7: Qui a l'autorite de decision directionnelle en cas de crise cyber? Cette information est t-elle communiqué ? | I7: Yes
B8: Business Continuity Plans (BCP) | C8: BCP Structure & Documentation | D8: Is there a formal, documented Business Continuity Plan? | E8: Ensure the existence of a formal and documented BCP that defines the organization’s approach to maintaining and restoring operations during disruptions | F8: PCA/BCP formel approuvé, politique de continuité, manuel de continuité, référentiel documentaire | G8: Exsite t-il un document formel de plan de contunite d'activite ? | I8: Yes
D9: Are document versions controlled and up to date? | E9: Ensure proper version control and regular updates of the BCP to maintain accuracy, traceability, and relevance | F9: Journal des versions, date de mise à jour, validation documentaire, contrôle qualité documentaire | G9: Les versions des documents sont-elles contrôlées et régulièrement mises à jour ? | I9: No
D10: Are data backup and restoration procedures documented? | E10: Ensure that data backup and restoration procedures are formally documented to support effective data recovery in case of disruption. | F10: Politique de sauvegarde, procédures de restauration, journaux de sauvegarde, rapports de tests | G10: Les procédures de sauvegarde et de restauration des données sont-elles formellement documentées | I10: Yes
D11: Are recovery strategies defined for each critical process? | E11: Ensure that appropriate recovery strategies are defined for each critical process to enable effective restoration of operations. | F11: Fiches stratégies par processus, PCA/PRA détaillés, scénarios de reprise, annexes opérationnelles | G11: Des stratégies de reprise sont-elles définies pour chaque processus critique | I11: Yes
D12: Are test results documented and analyzed? | E12: Ensure that test results are formally documented and analyzed to identify gaps and areas for improvement. | F12: Rapports d’évaluation, indicateurs de test, analyses d’écarts, tableaux de suivi | G12: Les résultats des tests sont-ils formellement documentés et analysés afin d’identifier les écarts et axes d’amélioration ? | I12: No
D13: Are employees aware of the BCP and their roles? | E13: Ensure that employees are aware of the BCP and understand their roles to enable an effective response during disruptions. | F13: Supports de sensibilisation, attestations de formation, quiz/exercices, enquêtes de connaissance | G13: Les employés sont-ils sensibilisés au PCA et à leurs rôles | I13: No
C14: Communication Management | D14: Les choix de stratégies sont-ils justifiés (coût, efficacité, risques) ? | E14: S’assurer que les choix de stratégies de continuité sont justifiés en termes de coût, d’efficacité et de risques afin d’assurer des décisions adaptées et optimisées. | F14: Études d’options, business case, analyse coûts-bénéfices, analyse de risques, PV de décision/validation | G14: Les choix de stratégies de continuité sont-ils formellement justifiés (coût, efficacité, risques) afin de garantir des décisions adaptées et optimisées ? | I14: No
C15: Testing & Exercises | D15: Existe-t-il une grille formelle de qualification des incidents ? | E15: S’assurer qu’une grille formelle de qualification des incidents est disponible afin de classer et prioriser les incidents de manière cohérente. | F15: Grille de qualification ; procédure de triage ; guide de classification | G15: Existe-t-il une grille formelle de qualification des incidents? | I15: Yes
D16: Des seuils d’escalade vers la gestion de crise sont-ils définis ? | E16: S’assurer que des seuils d’escalade vers la gestion de crise sont définis afin de déclencher rapidement les actions appropriées. | F16: Seuils d’escalade formalisés ; matrice d’escalade ; procédure d’activation de crise | G16: Des seuils d’escalade vers la gestion de crise sont-ils définis afin de déclencher rapidement les actions appropriées ? | I16: Yes
C17: Définition des Stratégies | D17: Existe-t-il un playbook formel pour les scénarios d’incident majeurs ? | E17: S’assurer qu’un playbook formel est disponible pour les scénarios d’incidents majeurs afin de guider la réponse et réduire les erreurs. | F17: Playbooks de réponse ; procédures par scénario ; fiches réflexes | G17: Existe-t-il des playbooks formels de confinement et de réponse pour les scénarios d’incidents majeurs afin de guider les actions et réduire les erreurs opérationnelles ? | I17: Yes
B18: STRATÉGIES DE CONTINUITÉ | C18: Procédure de signalement | D18: Les actions correctives post-incident sont-elles définies ? | E18: S’assurer que les actions correctives post-incident sont définies afin de prévenir la récurrence et améliorer la sécurité globale. | F18: Plan de remédiation ; registre des actions correctives ; suivi des corrections | G18: Les actions correctives post-incident sont-elles formellement définies et suivies afin de prévenir la récurrence et améliorer la sécurité globale ? | I18: N/A
B19: Détection et signalement | C19: Grille de qualification | D19: Les liens entre gestion de crise, gestion des incidents, continuité d’activité et sécurité sont-ils formalisés ? | E19: S’assurer que les liens entre gestion de crise, gestion des incidents, continuité d’activité et sécurité sont formalisés afin de garantir une coordination efficace et une réponse cohérente face aux disruptions. | F19: Schéma de gouvernance ; matrice d’articulation entre dispositifs ; procédure transversale validée | G19: Les liens entre la gestion de crise, la gestion des incidents, la continuité d’activité et la sécurité sont-ils formalisés afin d’assurer une coordination efficace et une réponse cohérente aux disruptions ? | I19: N/A
B20: Qualification et triage | C20: Critères de gravité | D20: Le cadre formel de gouvernance de gestion de crise cyber est-il documenté, daté et approuvé par l’autorité compétente ? | E20: S’assurer que le cadre de gouvernance de gestion de crise cyber est formellement documenté, daté et approuvé afin de garantir sa validité, sa légitimité et son application. | F20: Cadre de gouvernance approuvé ; note de validation signée ; version datée du document | G20: Le cadre de gouvernance de la gestion de crise cyber est-il formellement documenté, daté et approuvé par l’autorité compétente ? | I20: Yes
C21: Seuils d’escalade | D21: Existe-t-il une périodicité formelle de révision du cadre de gouvernance et les dernières versions sont-elles datées et tracées ? | E21: S’assurer qu’une périodicité de révision est définie et respectée afin de maintenir le cadre de gouvernance à jour et adapté aux évolutions. | F21: Calendrier de révision ; historique des versions ; journal des modifications | G21: Une périodicité de révision du cadre de gouvernance est-elle définie et respectée, et les versions sont-elles tracées et à jour ? | I21: Yes
C22: Rôles de triage | D22: Le cadre de gouvernance est-il communiqué aux parties prenantes concernées et cette diffusion est-elle traçable ? | E22: S’assurer que le cadre de gouvernance est communiqué aux parties prenantes et que cette diffusion est traçable afin de garantir sa bonne appropriation. | F22: Liste de diffusion ; emails de communication ; accusés de réception ou feuilles de diffusion | G22: Le cadre de gouvernance est-il communiqué aux parties prenantes concernées et cette diffusion est-elle traçable ? | I22: No
C23: Playbook de confinement | D23: Le personnel clé a-t-il reçu une formation sur la communication de crise ? | E23: S’assurer que le personnel clé est formé à la communication de crise afin de garantir une diffusion d’informations claire, cohérente et maîtrisée en situation de crise. | F23: Plan de formation ; feuilles de présence ; supports de sensibilisation | G23: Le personnel clé a-t-il reçu une formation sur la communication de crise afin de garantir une communication claire, cohérente et maîtrisée en situation de crise ? | I23: No
C24: Articulation avec les dispositifs connexes | D24: Do members have the required skills and competencies for their roles? | E24: S’assurer que les membres possèdent les compétences et savoir-faire requis pour leurs rôles afin d’assurer une réponse efficace. | F24: Matrice de compétences ; fiches de poste ; attestations de formation | G24: Les membres disposent-ils des compétences et aptitudes requises pour leurs rôles ? | I24: No
C25: Existence et approbation du cadre de gouvernance | D25: Are the members of the cell appointed formally? | E25: S’assurer que les membres de la cellule sont officiellement nommés afin de garantir responsabilité et clarté dans la structure de crise. | F25: Décision de nomination ; liste officielle des membres ; organigramme de crise | G25: Les membres de la cellule de crise sont-ils formellement désignés afin d’assurer une responsabilité claire et une structure de gouvernance définie | I25: No
C26: Diffusion du cadre aux parties prenantes concernées | D26: Existe-t-il des procédures pour évaluer la gravité d’un incident avant activation ? | E26: S’assurer que des procédures sont en place pour évaluer la gravité d’un incident avant activation afin de déclencher la cellule de crise de manière appropriée. | F26: Procédure d’évaluation ; grille de gravité ; procédure d’activation | G26: Les événements ou critères déclenchant l’activation de la cellule de crise sont-ils clairement définis afin d’assurer une réponse rapide et cohérente ? | I26: No
C27: Coordination et Information | D27: Existe-t-il des pénalités en cas de non-respect des exigences ? | E27: Ensure that penalties exist for non-compliance to enforce adherence to evidence management requirements. | F27: Clauses contractuelles ; SLA ; clauses de pénalité | G27: Des pénalités sont-elles prévues en cas de non-respect des exigences afin de garantir la conformité aux obligations de gestion des preuves ? | I27: Yes
D28: Les contrats incluent-ils des exigences de performance et de sécurité ? | E28: Ensure that contracts with service providers include performance and security requirements to safeguard evidence handling. | F28: Contrats fournisseurs ; exigences de sécurité ; annexes SLA/Security | G28: Les contrats avec les prestataires incluent-ils des exigences de performance et de sécurité afin de protéger la gestion et le traitement des preuves ? | I28: No
B29: Revue de direction et supervision | C29: Membership & Roles | D29: Les prestataires doivent-ils fournir des rapports d’audit ou certifications ? | E29: Ensure that service providers are required to provide audit reports or certifications to verify compliance and reliability. | F29: Clauses d’audit ; rapports d’audit ; certificats de conformité | G29: Les prestataires sont-ils tenus de fournir des rapports d’audit ou des certifications afin de démontrer leur conformité et leur fiabilité ? | I29: Yes
D30: Existe-t-il une politique formelle de conservation des preuves numériques ? | E30: Ensure a formal digital evidence retention policy exists to guarantee proper handling, preservation, and management of digital evidence. | F30: Politique de conservation des preuves ; procédure forensique ; note d’approbation | G30: Existe-t-il une politique formelle de conservation des preuves numériques ? | I30: Yes
D31: Cette durée respecte-t-elle les exigences légales et réglementaires (ISO 27001) | E31: Ensure that evidence retention duration complies with legal and regulatory requirements (e.g., ISO 27001). | F31: Politique de rétention ; matrice de conformité ; avis juridique ou conformité | G31: La durée de conservation respecte-t-elle les exigences légales et réglementaires (ISO 27001) ? | I31: Yes
B32: Communication de crise | C32: Coordination & Escalation | D32: Les preuves sont-elles conservées suffisamment longtemps pour les enquêtes ? | E32: Ensure that evidence is retained long enough to support thorough investigations and legal proceedings. | F32: Tableau des durées de conservation ; exigences d’enquête ; registre d’archivage | I32: Yes
C33: Process & Procedures | D33: Une durée de conservation des preuves est-elle définie ? | E33: Ensure that a defined retention period for evidence is established to guide proper management. | F33: Politique de rétention ; calendrier de conservation ; procédure d’archivage | I33: Yes
B34: Organisation et fonctionnement de la cellule | D34: Les procédures respectent-elles les bonnes pratiques forensiques (ISO 27037) ? | E34: Ensure that procedures follow forensic best practices (e.g., ISO 27037) to maintain credibility and legal admissibility. | F34: Procédure forensique ; référentiel de bonnes pratiques ; mode opératoire d’investigation | G34: Les procédures respectent-elles les bonnes pratiques forensiques (ISO 27037) ? | I34: Yes
C35: Audit et droit de contrôle | D35: Les preuves sont-elles exploitables dans un cadre légal (admissibilité) ? | E35: Ensure that collected evidence is legally admissible to support investigations and potential legal action. | F35: Chaîne de possession ; avis juridique ; dossier de preuve documenté | G35: Les preuves sont-elles exploitables dans un cadre légal (admissibilité) ? | I35: Yes
D36: interdit à tout chargé de l’exécution des ordonnances judiciaires relatives à l’accès aux données stockées au niveau du système d’information ou à la collecte de données du flux de trafic ou à l’interception de communications, ou celui auquel il est fait recours pour cette tâche, de divulguer le secret professionnel dans tout ce qui concerne les dispositions et les modalités appliquées ou les informations ou données | E36: S’assurer que la confidentialité des opérations liées à l’accès, la collecte et l’interception des données est strictement respectée afin de protéger le secret professionnel et les informations sensibles | F36: Declaration signe de charge des son premier jour de sa prise en charge de travaille | G36: La confidentialité des opérations d’accès, de collecte et d’interception des données est-elle strictement respectée afin de protéger le secret professionnel ? | I36: Yes

Sheet Questionnaire Gestion de crise
L2: Nb Question | N2: Nb App | O2: Yes | P2: No | Q2: N/A | R2: SCORE DU DOMAIN
B3: Domaine | C3: Sous Domaine | D3: Catégorie de contrôle | E3: Contrôle | F3: Objectif | G3: Preuves possibles | H3: Question finale | J3: Result | L3: =COUNTA(H4:H25) -> 21 | N3: =L3-Q3 -> 20 | O3: =COUNTIF(J4:J21,"Yes") -> 16 | P3: =COUNTIF(J4:J21,"No") -> 0 | Q3: =COUNTIF(J4:J21,"N/A") -> 1 | R3: =O3/N3 -> 0.8
B4: Gestion de CRISE | C4: Communication de crise | D4: Coordination et Information | E4: Quels canaux de communication sont prévus pour la diffusion externe/interne ? | F4: S’assurer que des canaux de communication externes sont prévus afin de diffuser rapidement et clairement les informations aux parties prenantes externes. | G4: Plan de communication de crise ; liste des canaux externes ; modèles de communiqués | H4: What communication channels are established for use in the event of an cybercrise? | I4: ISO/IEC 27002:2022, 5.24 / 5.26 / 5.14 ; NIST SP 800-61 Rev.3 / NIST CSF 2.0, RS.CO | J4: N/A
F5: S’assurer que des canaux de communication internes sont prévus afin de tenir informé le personnel et les parties prenantes internes. | G5: Procédure de communication interne ; annuaire de diffusion ; canaux d’alerte définis | I5: ISO/IEC 27002:2022, 5.24 / 5.26 / 6.3 / 6.8 ; NIST SP 800-61 Rev.3 / NIST CSF 2.0, RS.CO
D6: Continuité de la communication | E6: Mise en place de canaux de communication alternatifs et sécurisés en cas de compromission des systèmes internes | F6: S’assurer que la communication interne et externe peut être maintenue même en cas d’indisponibilité ou de compromission des systèmes d’information | G6: Plan de communication de crise ; liste des canaux alternatifs (messagerie externe, téléphones, outils hors SI interne) ; procédures de bascule ; tests de continuité | H6: La communication peut-elle être maintenue si les systèmes internes sont compromis ? | I6: ISO/IEC 27002:2022, 5.29 / 5.30 / 5.14 ; NIST CSF 2.0, PR.IR / RS.CO / RC.CO | J6: Yes
C7: Organisation et fonctionnement de la cellule | D7: Structure | E7: La cellule de gestion de crise est-elle formellement établie au sein de l’organisation ? | F7: S’assurer que la cellule de gestion de crise est formellement établie au sein de l’organisation afin de garantir sa légitimité, sa structure et une autorité claire pour la gestion des situations de crise. | G7: Charte de cellule de crise ; note de gouvernance ; document d’organisation validé | H7: Les membres de la cellule de crise sont-ils identifiés (IT, sécurité, juridique, communication, direction) ? | I7: ISO/IEC 27002:2022, 5.2 / 5.4 / 5.24 ; NIST CSF 2.0, GV.RR / RS.MA | J7: Yes | L7: Auditeur | M7: Oumayma
H8: Les rôles et responsabilités sont-ils clairement définis et compris ? Existe-t-il des remplaçants en cas d’indisponibilité ? | I8: ISO/IEC 27002:2022, 5.2 / 5.4 / 5.24 ; NIST CSF 2.0, GV.RR / RS.MA | J8: Yes
C9: Détection et déclenchement de crise | D9: Surveillance | E9: Mise en place d’outils de monitoring en temps réel (SIEM, EDR, NDR) | F9: Assurer une détection rapide et proactive des incidents majeurs | G9: Outils SIEM/EDR/NDR ; tableaux de bord de supervision ; alertes en temps réel ; procédures de surveillance | H9: Les outils de monitoring permettent-ils une détection en temps réel des incidents majeurs ? | I9: ISO/IEC 27002:2022, 8.15 / 8.16 / 8.17 ; NIST CSF 2.0, DE.CM / DE.AE | J9: Yes
C10: Procédures de réponse | D10: Opérationnelle | E10: Définition de procédures d’isolement des systèmes compromis | F10: Réduire la propagation des incidents et limiter leur impact | G10: Procédures d’isolement ; playbooks SOC ; journaux d’intervention ; rapports d’incident | H10: Combien de temps faut-il en moyenne pour isoler un système compromis ? | I10: ISO/IEC 27002:2022, 5.26 / 8.7 / 8.20 / 8.22 ; NIST SP 800-61 Rev.3 / NIST CSF 2.0, RS.MI | J10: Yes
E11: Élaboration et mise à disposition de runbooks pour les scénarios cyber majeurs | F11: Standardiser et accélérer la réponse aux incidents critiques | G11: Runbooks documentés ; playbooks d’intervention ; documentation SOC ; guides opérationnels | H11: Des runbooks sont-ils disponibles pour les scénarios cyber majeurs | I11: ISO/IEC 27002:2022, 5.26 / 5.37 ; NIST SP 800-61 Rev.3 / NIST CSF 2.0, RS.MA / RS.MI | J11: Yes
C12: Coordination externe | D12: CERT | E12: Contractualisation avec un prestataire de réponse à incident (IR) | F12: Garantir un support expert en cas de crise cyber majeure | G12: Contrats IR ; SLA ; coordonnées du prestataire ; procédures d’escalade | H12: Un prestataire de réponse à incident (IR) est-il contractuellement prévu ? | I12: ISO/IEC 27002:2022, 5.19 / 5.20 / 5.21 / 5.22 ; NIST CSF 2.0, GV.SC / RS.MA | J12: Yes
E13: Mise en place de mécanismes de communication avec CERT/autorités | F13: Faciliter la collaboration avec les autorités compétentes | G13: Procédures de notification ; registre réglementaire ; rapports de conformité | H13: Existe-t-il un mécanisme de communication avec CERT/autorités ? | I13: ISO/IEC 27002:2022, 5.5 / 5.6 / 5.24 / 6.8 ; NIST SP 800-61 Rev.3 / NIST CSF 2.0, RS.CO | J13: Yes
D14: Fournisseurs | E14: Intégration des parties prenantes externes dans la gestion de crise | F14: Assurer une coordination efficace avec fournisseurs et partenaires | G14: Plan de gestion de crise ; liste des contacts ; procédures de coordination externe | H14: Comment La coordination avec fournisseurs, cloud providers et partenaires est-elle intégrée dans la gestion de crise ? | I14: ISO/IEC 27002:2022, 5.19 / 5.20 / 5.21 / 5.22 / 5.23 ; NIST CSF 2.0, GV.SC / RS.CO | J14: Yes
C15: Indicateurs opérationnels | D15: KPI | E15: Suivi des indicateurs MTTD et MTTR | F15: Mesurer la performance de détection et de réponse | G15: Tableaux de bord KPI ; rapports SOC ; indicateurs de performance | H15: Le temps de détection (MTTD) et de réponse (MTTR) est-il mesuré ? | I15: ISO/IEC 27002:2022, 5.25 / 5.26 / 8.16 ; NIST SP 800-61 Rev.3 / NIST CSF 2.0, DE.CM / RS.MA / ID.IM | J15: Yes
E16: Évaluation régulière des performances en gestion de crise | F16: Améliorer en continu les capacités de réponse | G16: Rapports d’audit ; REX ; tableaux de performance ; comptes rendus | H16: Les performances en gestion de crise sont-elles régulièrement évaluées ? | I16: ISO/IEC 27002:2022, 5.27 / 5.35 / 5.36 / 5.37 ; NIST CSF 2.0, ID.IM | J16: Yes
C17: Veille et préparation à la crise | D17: Threat Intelligence | E17: Mise en place d’une capacité de Threat Intelligence | F17: Anticiper les menaces et améliorer la détection | G17: Rapports CTI ; flux de renseignement ; outils TI ; analyses de menaces | H17: L’organisation collecte-t-elle et exploite-t-elle efficacement les renseignements sur les menaces (stratégiques, tactiques et opérationnelles) pour anticiper les crises cyber, améliorer la détection et réduire leur impact ? | I17: ISO/IEC 27002:2022, 5.7 / 8.16 ; NIST CSF 2.0, ID.RA / DE.CM | J17: Yes
E18: Analyse des incidents de sécurité et retour d’expérience | F18: Réduire les incidents récurrents et améliorer la posture de sécurité | G18: Rapports d’incident ; base de données incidents ; analyses de tendances | H18: L’organisation mesure-t-elle et analyse-t-elle les incidents de sécurité (types, volume, coûts) afin d’améliorer la gestion de crise, prévenir les incidents récurrents et renforcer la sensibilisation des utilisateurs ? | I18: ISO/IEC 27002:2022, 5.27 / 5.24 / 5.26 ; NIST SP 800-61 Rev.3 / NIST CSF 2.0, RS.AN / ID.IM | J18: Yes
C19: Tests et amélioration | D19: Tests | E19: Organisation d’exercices de simulation de crise | F19: Tester et améliorer la préparation de l’organisation | G19: Rapports d’exercice ; scénarios de crise ; comptes rendus | H19: Des exercices de simulation de crise sont-ils réalisés ? | I19: ISO/IEC 27002:2022, 5.24 / 5.29 / 5.30 ; NIST CSF 2.0, ID.IM / PR.IR | J19: Yes
D20: Historique | E20: Activation réelle de la cellule de crise | F20: Évaluer l’efficacité en conditions réelles | G20: Rapports d’incident ; comptes rendus de crise ; REX | H20: La cellule a-t-elle déjà été activée en conditions réelles ? | I20: ISO/IEC 27002:2022, 5.27 ; NIST CSF 2.0, ID.IM | J20: Yes
C21: Disponibilité des ressources | D21: Ressources | E21: Mise en place d’une organisation de crise disponible 24/7 | F21: Garantir une réponse immédiate aux incidents majeurs | G21: Planning d’astreinte ; organisation SOC ; procédures d’escalade | H21: Les équipes de crise sont-elles disponibles 24/7 en cas d’incident majeur ? | I21: ISO/IEC 27002:2022, 5.2 / 5.4 / 5.24 / 5.26 ; NIST CSF 2.0, GV.RR / RS.MA | J21: Yes
E22: Définition d’un espace dédié de gestion de crise | F22: Assurer une gestion structurée des crises | G22: Salle de crise ; outils collaboratifs ; plateformes de gestion de crise | H22: Existe-t-il un espace dédié de gestion de crise (physique ou virtuel) ? | I22: ISO/IEC 27002:2022, 7.1 / 7.2 / 5.29 / 5.30 ; NIST CSF 2.0, PR.IR / RS.MA | J22: Yes
C23: Gestion des données en crise | D23: Data | E23: Mise en place de procédures d’identification et de protection des données compromises | F23: Limiter l’impact sur les données sensibles | G23: Procédures de gestion des données ; classification ; journaux d’accès | H23: Comment les données compromises sont-elles identifiées et protégées ? | I23: ISO/IEC 27002:2022, 5.12 / 5.13 / 5.34 / 8.12 / 8.15 ; NIST CSF 2.0, PR.DS / RS.AN / RS.MA | J23: Yes
C24: Reprise après crise | D24: Restauration | E24: Mise en œuvre de procédures de restauration sécurisée des systèmes | F24: Assurer une reprise fiable et sécurisée des activités | G24: procédures de restauration ; journaux de repris | H24: Comment Les systèmes sont-ils restaurés de manière contrôlée et sécurisée ? | I24: ISO/IEC 27002:2022, 5.30 / 8.13 / 8.14 ; NIST SP 800-61 Rev.3 / NIST CSF 2.0, RC.RP / RC.CO | J24: Yes
D25: Validation | E25: Réalisation de contrôles post-crise avant remise en production | F25: Éviter la réintroduction de vulnérabilités | G25: Rapports de validation ; tests post-restauration ; audits | H25: Un contrôle post-crise est-il effectué avant la remise en production ? | I25: ISO/IEC 27002:2022, 5.27 / 8.8 / 8.29 / 8.32 ; NIST CSF 2.0, ID.IM / RC.RP | J25: Yes

Sheet Question Continuité d’activité
L2: Nb Question | N2: Nb app | O2: Yes | P2: No | Q2: N/A | R2: SCORE DU DOMAIN
B3: Domaine | C3: Sous Domaine | D3: Catégorie de contrôle | E3: Contrôle | F3: Objectif | G3: Preuves possibles | H3: Question finale | I3: Refernces | J3: Result | L3: =COUNTA(H4:H25) -> 11 | N3: =L3-Q3 -> 8 | O3: =COUNTIF(J4:J25,"Yes") -> 4 | P3: =COUNTIF(J4:J25,"No") -> 4 | Q3: =COUNTIF(J4:J25,"N/A") -> 3 | R3: =O3/N3 -> 0.5
B4: Domain Du Continuité d’activité | C4: Business Impact Analysis (BIA) | D4: Identification des activités critiques | E4: Les processus métiers sont-ils priorisés en fonction de leur criticité ? | F4: S’assurer que toutes les dépendances internes et externes nécessaires au fonctionnement des processus métiers sont identifiées de manière exhaustive. | G4: Registre des processus métiers classés par criticité, matrice de priorisation, rapport BIA validé | H4: Comment les processus métiers sont-ils identifiés, priorisés et classifiés ? | I4: ISO 22301:2019 8.2.2(b), 8.2.2(f) ; ISO/IEC 27001:2022 Annexe A A.5..9 | J4: N/A | S4: Auditeur | T4: Dhia
E5: Comment les processus critiques sont-ils identifiés et classifiés ? | F5: S’assurer qu’une méthodologie structurée et cohérente est utilisée pour identifier et classer les processus métiers critiques en fonction de leur importance pour les opérations et les objectifs de l’organisation. | G5: Méthodologie BIA, critères de classification documentés, grille de scoring, comptes rendus d’ateliers métiers
E6: Les dépendances externes (fournisseurs, partenaires) sont-elles incluses dans le BIA ? | F6: S’assurer que toutes les dépendances liées aux tiers sont prises en compte dans le BIA afin d’évaluer les risques liés aux perturbations externes et de renforcer la résilience. | G6: Liste des fournisseurs/partenaires critiques, cartographie des dépendances externes, contrats/SLA, sections BIA dédiées aux tiers | H6: Toutes les dépendances internes et externes, y compris les fournisseurs, partenaires, systèmes informatiques et le personnel, ont-elles été identifiées et intégrées dans le BIA ? | I6: ISO 22301:2019 8.2.2(g), 8.2.2(h) ISO/IEC 27001:2022 Annexe A A.5.19 | J6: Yes
E7: Toutes les dépendances ont-elles été identifiées (systèmes IT, tiers, personnel) ? | F7: S’assurer que toutes les dépendances internes et externes nécessaires au fonctionnement des processus métiers sont identifiées de manière exhaustive afin d’éviter les vulnérabilités cachées. | G7: Cartographie des dépendances, inventaire applicatif, organigrammes/fiches de postes clés, registre des tiers critiques
D8: Impact Analysis | E8: Des mesures d’impact quantitatives et/ou qualitatives sont-elles utilisées ? | F8: S’assurer que des mesures à la fois quantitatives et qualitatives sont utilisées afin de fournir une évaluation complète des impacts. | G8: Tableaux d’évaluation chiffrée, indicateurs qualitatifs, scorecards, fiches d’analyse d’impact | H8: Les impacts sont-ils mesurés quantitativement et/ou qualitativement, et sont-ils évalués à court, moyen et long terme (24h, 48h, 72h) ? | I8: ISO 22301:2019 8.2.2 ; ISO/IEC 27001:2022 Annexe A A.5.30 | J8: N/A
E9: Les impacts sont-ils évalués selon plusieurs horizons temporels (ex. : 24h, 48h, 72h) ? | F9: S’assurer que les impacts sont analysés selon différents horizons temporels afin de comprendre l’évolution de la gravité des perturbations et de définir des priorités de reprise adaptées. | G9: Tableaux d’impact par horizon temporel, scénarios de dégradation, rapport BIA avec seuils 24h/48h/72h, matrices d’escalade
C10: Business Continuity Plans (BCP) | D10: Responsibilitiés | E10: Les différents types de scénarios sont-ils couverts (cyberattaque, panne système) ? | F10: S’assurer que le PCA couvre une gamme de scénarios de perturbation plausibles afin d’améliorer la préparation et l’efficacité de la réponse. | G10: Bibliothèque de scénarios, plans par scénario, fiches réflexes, analyses de risques | H10: Le PCA couvre-t-il différents types de scénarios avec des procédures de réponse détaillées pour chacun ? | I10: ISO 22301:2019 8.4.1, 8.4.4 ; ISO/IEC 27001:2022 Annexe A A.5.29 | J10: No
E11: Les procédures de réponse détaillées sont-elles définies pour chaque scénario ? | F11: S’assurer que des procédures de réponse détaillées, étape par étape, sont définies pour chaque scénario afin de permettre une réponse structurée et efficace en cas de perturbation. | G11: Procédures détaillées, playbooks, runbooks, fiches réflexes par scénario
D12: Procédures de réponse | E12: Les listes de contacts (internes et externes) sont-elles documentées et régulièrement mises à jour ? | F12: S’assurer que des informations de contact précises et à jour sont maintenues afin de permettre une communication et une coordination rapides en situation de crise. | G12: Annuaire de crise, listes d’appel, contacts fournisseurs, historique de mise à jour | H12: Les listes de contacts (internes et externes) sont-elles documentées et régulièrement mises à jour ? | I12: ISO 22301:2019 8.4.3 ; ISO/IEC 27001:2022 Annexe A A.5.5 | J12: N/A
E13: es procédures de communication (internes et externes) sont-elles définies ? | F13: S’assurer que des procédures de communication claires sont définies pour les parties prenantes internes et externes afin de garantir une diffusion cohérente et coordonnée de l’information. | G13: Procédure de communication de crise, matrices de communication, modèles de messages, plan média
D14: Communication Management | E14: Des modèles de communication de crise (emails, communiqués de presse) sont-ils préparés ? | F14: S’assurer que des modèles de communication préapprouvés sont disponibles afin de garantir des messages rapides, cohérents et maîtrisés en situation de crise. | G14: Modèles de messages, communiqués préapprouvés, modèles d’email/SMS, kit de communication
D15: Resource Management | E15: Le personnel critique est-il identifié et formé ? | F15: S’assurer que le personnel critique est identifié et correctement formé pour assurer ses missions en cas de perturbation. | G15: Liste du personnel critique, plan de formation, feuilles de présence, exercices ciblés | H15: Comment l’entreprise s’assure-t-elle que les équipes connaissent leurs rôles en cas de crise ? | I15: ISO 22301:2019 8.4.2.2, 8.4.2.4 ; ISO/IEC 27001:2022 Annexe A A.5.2 | J15: Yes
H16: Le personnel critique a-t-il été identifié et formé de manière appropriée pour faire face aux perturbations ? | I16: ISO 22301:2019 7.2, §7.3 ; ISO/IEC 27001:2022 Annexe A A.6.3 | J16: Yes
D17: Procedures de reponse | E17: Les capacités de restauration sont-elles testées ? | F17: S’assurer que les capacités de restauration sont régulièrement testées afin de valider leur efficacité en situation réelle. | G17: Rapports de tests de restauration, preuves de succès/échec, journaux techniques, PV d’exercice PRA | H17: Quand les scénarios du BIA ont-ils été testés pour la dernière fois et quels types de tests ont été réalisés ? | I17: ISO 22301:2019 §8.5 ; ISO/IEC 27001:2022 Annexe A A.5.30 | J17: No
D18: Testing & Exercises | E18: Différents types de tests sont-ils réalisés (tabletop, techniques, à grande échelle) ? | F18: S’assurer qu’une variété de tests (tabletop, techniques, à grande échelle) est réalisée afin d’évaluer de manière complète les différents aspects du PCA. | G18: Programme d’exercices, rapports distincts par type de test, scénarios tabletop/techniques/full-scale
D19: Stratégies IT | E19: Des ressources de secours sont-elles disponibles et documentées ? | F19: S’assurer que des ressources de secours sont disponibles et correctement documentées afin de garantir la continuité en cas de défaillance des ressources. | G19: Contrats de secours, équipements redondants, fournisseurs alternatifs, stock de sécurité | H19: Votre organisation dispose-t-elle d’une solution de réplication et/ou de sauvegarde des données ? | I19: ISO 22301:2019 §8.3.4(b), §8.3.4(e) ; ISO/IEC 27001:2022 Annexe A A.8.13, A.8.14 | J19: Yes
E20: Les données sont-elles sauvegardées régulièrement ? | F20: S’assurer que les données sont sauvegardées de manière régulière afin de limiter la perte de données en cas d’incident. | G20: Politique de sauvegarde, planning des sauvegardes, logs de sauvegarde, tableaux de suivi
E21: Les solutions de réplication des données sont-elles mises en place ? | F21: S’assurer que des solutions de réplication des données sont mises en place afin de garantir la disponibilité et la résilience des données critiques. | G21: Architecture de réplication, configurations techniques, contrats/outils de réplication, tableaux de bord de supervision
C22: STRATÉGIES DE CONTINUITÉ | D22: Stratégies Opérationnelles | E22: Existe-t-il des plans de relocalisation des équipes ? | F22: S’assurer que des plans de relocalisation des équipes sont définis afin de maintenir les opérations en cas d’indisponibilité des sites principaux. | G22: Plan de relocalisation, sites alternatifs identifiés, accords logistiques, scénarios de transfert testés | H22: Les plans de relocalisation, les sites alternatifs, les accords logistiques ainsi que les environnements de reprise d’activité (PRA) ,incluant les contrats, la documentation et l’architecture cible sont-ils définis, documentés et testés (y compris les scénarios de transfert) ? | I22: ISO 22301:2019 8.3.4, 8.3.5, 8.5 ; ISO/IEC 27001:2022 Annexe A A.5.30 | J22: No
G23: Liste de ressources de secours, contrats de secours, solutions alternatives documentées, sites/relais identifiés
D24: Recovery Strategies | E24: Les sites alternatifs sont-ils modifiés ? | F24: S’assurer que des sites ou systèmes alternatifs sont identifiés afin de maintenir ou de rétablir les opérations lorsque les ressources principales sont indisponibles. | G24: Contrats/site de repli, documentation DR site, inventaire environnements de secours, architecture cible
D25: Resource Management | E25: L’entreprise intègre-t-elle les retours d’expérience dans les plans de continuité ? | F25: S’assurer que les retours d’expérience (incidents, exercices, tests) sont systématiquement analysés, documentés et intégrés dans les plans, afin de garantir l’amélioration continue de l’efficacité des dispositifs de continuité. | G25: Rapports de retour d’expérience, comptes rendus d’exercices/tests, plans mis à jour, procédures de gestion des changements, historiques des améliorations. | H25: Comment l’entreprise s’assure-t-elle que les retours d’expérience sont intégrés dans les plans ? | I25: ISO 22301:2019 8.6, 10.2 ; ISO/IEC 27001:2022 Annexe A A.5.27 | J25: No

Sheet Questionnaire Domain Forensics
N2: Nb Question | P2: Nb app | Q2: Yes | R2: No | S2: N/A | T2: SCORE DU DOMAIN
B3: Domaine | C3: Sous Domaine | D3: Catégorie de contrôle | E3: Contrôle | F3: Objectif | G3: Preuves possibles | H3: Question finale | I3: reference | J3: Result | N3: =COUNTA(H4:H13) -> 4 | P3: =N3-S3 -> 3 | Q3: =COUNTIF(J4:J10,"Yes") -> 2 | R3: =COUNTIF(J4:J10,"No") -> 0 | S3: =COUNTIF(J4:J10,"N/A") -> 1 | T3: =Q3/P3 -> 0.66666667
B4: Forensics | C4: Exigences de conservation de preuve | D4: cadre de gestion des preuves | E4: Les types de preuves (logs, images disque, emails, etc.) sont-ils identifiés ? | F4: S’assurer que tous les types de preuves pertinents (journaux, images disque, e-mails, etc.) sont identifiés afin de soutenir des investigations approfondies. | G4: Typologie des preuves ; guide de collecte ; inventaire des sources de preuve | H4: Quel est le périmètre de la collecte des preuves et quels outils sont utilisés pour cette collecte ? | I4: iso 27037 clause 5 . ISO/IEC 27001:2022 - 5.28 | J4: Yes
E5: Les outils de collecte utilisés sont-ils validés et fiables ? | F5: S’assurer que les outils de collecte sont validés et fiables afin de garantir l’intégrité et l’exactitude des preuves. | G5: Liste des outils approuvés ; rapports de validation ; documentation technique | I5: iso 27037 clause 6 . ISO/IEC 27001:2022 - 5.28
D6: Identification et collecte des preuves | E6: Les intervenants savent-ils quoi collecter et quand ? | F6: S’assurer que le personnel sait quelles preuves collecter et à quel moment, afin de soutenir des processus forensiques efficaces. | G6: Guide opérationnel ; supports de formation ; fiches réflexes | H6: Les personnes chargées de la collecte des preuves sont-elles qualifiées pour effectuer cette tâche, et quelle méthode de collecte est utilisée ? | I6: iso 27037 clause 6 + annexe A ; ISO/IEC 27001:2022 - 5.28 | J6: Yes | N6: Auditeur | O6: Oumayma
E7: Les méthodes de collecte garantissent-elles l’intégrité des preuves ? | F7: S’assurer que les méthodes de collecte préservent l’intégrité des preuves afin d’éviter toute altération ou perte. | G7: Procédure de collecte ; chaîne de conservation ; formulaires de traçabilité | I7: iso 27037 clause 6-7 . ISO/IEC 27001:2022 - 5.28
D8: Stockage et protection des preuves | E8: L’accès au stockage est-il limité aux personnes autorisées ? | F8: S’assurer que l’accès au stockage des preuves est restreint au personnel autorisé afin de protéger la confidentialité et l’intégrité. | G8: Matrice des habilitations ; journal des accès ; procédure de contrôle d’accès | H8: Où sont stockées les preuves et qui peut y accéder ? | I8: iso 27037 clause 6 . ISO/IEC 27001:2022 6A.8.3 + A.8.15 | J8: N/A
E9: Des sauvegardes des preuves sont-elles réalisées ? | F9: S’assurer que des sauvegardes des preuves sont effectuées afin d’éviter toute perte accidentelle ou corruption. | G9: Politique de sauvegarde ; journaux de sauvegarde ; rapports de test de restauration | I9: iso 27037 clause 6 . ISO/IEC 27001:2022 -A.8.13
E10: Les preuves sont-elles stockées dans un environnement sécurisé ? | F10: S’assurer que les preuves sont stockées dans un environnement sécurisé afin de les protéger contre tout accès non autorisé ou dommage. | G10: Procédure de stockage sécurisé ; configuration du coffre ou dépôt sécurisé ; contrôle d’accès physique/logique | I10: iso 27037 clause 6+7 + Annexe B . ISO/IEC 27001:2022- A.7.8 + A.8.15
H11: Comment l’entreprise s’assure-t-elle que les enregistrements sont complets et n’ont fait l’objet d’aucune altération ? | I11: iso 27037 clause 6+7 + Annexe B . ISO/IEC 27001:2022- A.5.28 + A.8.15 | J11: No

Sheet FinalResult
A1: Domaine | B1: NbQuestion | C1: NbQuestionApp | D1: Yes | E1: No | F1: N/A | G1: ScoreDomain | H1: Ponderation | I1: Auditeur
A2: Forensics | B2: ='Questionnaire Domain Forensics'!$N$3 -> 4 | C2: ='Questionnaire Domain Forensics'!$P$3 -> 3 | D2: ='Questionnaire Domain Forensics'!$Q$3 -> 2 | E2: ='Questionnaire Domain Forensics'!$R$3 -> 0 | F2: ='Questionnaire Domain Forensics'!$S$3 -> 1 | G2: ='Questionnaire Domain Forensics'!$T$3 -> 0.66666667 | H2: =PONDERATION!$L$20 -> 6 | I2: ='Questionnaire Domain Forensics'!$O$6 -> Oumayma
A3: Continuité d’activité | B3: ='Question Continuité d’activité'!$L$3 -> 11 | C3: ='Question Continuité d’activité'!$N$3 -> 8 | D3: ='Question Continuité d’activité'!$O$3 -> 4 | E3: ='Question Continuité d’activité'!$P$3 -> 4 | F3: ='Question Continuité d’activité'!$Q$3 -> 3 | G3: ='Question Continuité d’activité'!$R$3 -> 0.5 | H3: =PONDERATION!$L$19 -> 23 | I3: ='Question Continuité d’activité'!$T$4 -> Dhia
